[2022-11-08T22:33:37.339+0000] {taskinstance.py:1165} INFO - Dependencies all met for <TaskInstance: forex_data_pipeline.downloading_rates manual__2022-11-08T22:31:32.640798+00:00 [queued]>
[2022-11-08T22:33:37.351+0000] {taskinstance.py:1165} INFO - Dependencies all met for <TaskInstance: forex_data_pipeline.downloading_rates manual__2022-11-08T22:31:32.640798+00:00 [queued]>
[2022-11-08T22:33:37.353+0000] {taskinstance.py:1362} INFO - 
--------------------------------------------------------------------------------
[2022-11-08T22:33:37.354+0000] {taskinstance.py:1363} INFO - Starting attempt 2 of 4
[2022-11-08T22:33:37.355+0000] {taskinstance.py:1364} INFO - 
--------------------------------------------------------------------------------
[2022-11-08T22:33:37.369+0000] {taskinstance.py:1383} INFO - Executing <Task(PythonOperator): downloading_rates> on 2022-11-08 22:31:32.640798+00:00
[2022-11-08T22:33:37.374+0000] {standard_task_runner.py:54} INFO - Started process 4884 to run task
[2022-11-08T22:33:37.377+0000] {standard_task_runner.py:82} INFO - Running: ['***', 'tasks', 'run', 'forex_data_pipeline', 'downloading_rates', 'manual__2022-11-08T22:31:32.640798+00:00', '--job-id', '22', '--raw', '--subdir', 'DAGS_FOLDER/forex_data_pipeline.py', '--cfg-path', '/tmp/tmp96n8w54c']
[2022-11-08T22:33:37.378+0000] {standard_task_runner.py:83} INFO - Job 22: Subtask downloading_rates
[2022-11-08T22:33:37.379+0000] {dagbag.py:525} INFO - Filling up the DagBag from /opt/***/dags/forex_data_pipeline.py
[2022-11-08T22:33:37.467+0000] {task_command.py:384} INFO - Running <TaskInstance: forex_data_pipeline.downloading_rates manual__2022-11-08T22:31:32.640798+00:00 [running]> on host f6a61415b844
[2022-11-08T22:33:37.524+0000] {taskinstance.py:1592} INFO - Exporting the following env vars:
AIRFLOW_CTX_DAG_EMAIL=juanfelipehdezm@gmail.com
AIRFLOW_CTX_DAG_OWNER=felipehdez
AIRFLOW_CTX_DAG_ID=forex_data_pipeline
AIRFLOW_CTX_TASK_ID=downloading_rates
AIRFLOW_CTX_EXECUTION_DATE=2022-11-08T22:31:32.640798+00:00
AIRFLOW_CTX_TRY_NUMBER=2
AIRFLOW_CTX_DAG_RUN_ID=manual__2022-11-08T22:31:32.640798+00:00
[2022-11-08T22:33:38.128+0000] {taskinstance.py:1851} ERROR - Task failed with exception
Traceback (most recent call last):
  File "/home/airflow/.local/lib/python3.7/site-packages/airflow/operators/python.py", line 175, in execute
    return_value = self.execute_callable()
  File "/home/airflow/.local/lib/python3.7/site-packages/airflow/operators/python.py", line 193, in execute_callable
    return self.python_callable(*self.op_args, **self.op_kwargs)
  File "/opt/airflow/dags/forex_data_pipeline.py", line 25, in download_rates
    with open("/opt/files/rates.json", "w") as outfil:
FileNotFoundError: [Errno 2] No such file or directory: '/opt/files/rates.json'
[2022-11-08T22:33:38.143+0000] {taskinstance.py:1406} INFO - Marking task as UP_FOR_RETRY. dag_id=forex_data_pipeline, task_id=downloading_rates, execution_date=20221108T223132, start_date=20221108T223337, end_date=20221108T223338
[2022-11-08T22:33:38.158+0000] {warnings.py:110} WARNING - /home/***/.local/lib/python3.7/site-packages/***/utils/email.py:120: RemovedInAirflow3Warning: Fetching SMTP credentials from configuration variables will be deprecated in a future release. Please set credentials using a connection instead.
  send_mime_email(e_from=mail_from, e_to=recipients, mime_msg=msg, conn_id=conn_id, dryrun=dryrun)

[2022-11-08T22:33:38.160+0000] {configuration.py:569} WARNING - section/key [smtp/smtp_user] not found in config
[2022-11-08T22:33:38.161+0000] {email.py:229} INFO - Email alerting: attempt 1
[2022-11-08T22:33:38.167+0000] {configuration.py:569} WARNING - section/key [smtp/smtp_user] not found in config
[2022-11-08T22:33:38.168+0000] {email.py:229} INFO - Email alerting: attempt 1
[2022-11-08T22:33:38.169+0000] {taskinstance.py:1914} ERROR - Failed to send email to: juanfelipehdezm@gmail.com
Traceback (most recent call last):
  File "/home/airflow/.local/lib/python3.7/site-packages/airflow/models/taskinstance.py", line 1457, in _run_raw_task
    self._execute_task_with_callbacks(context, test_mode)
  File "/home/airflow/.local/lib/python3.7/site-packages/airflow/models/taskinstance.py", line 1603, in _execute_task_with_callbacks
    result = self._execute_task(context, task_orig)
  File "/home/airflow/.local/lib/python3.7/site-packages/airflow/models/taskinstance.py", line 1664, in _execute_task
    result = execute_callable(context=context)
  File "/home/airflow/.local/lib/python3.7/site-packages/airflow/operators/python.py", line 175, in execute
    return_value = self.execute_callable()
  File "/home/airflow/.local/lib/python3.7/site-packages/airflow/operators/python.py", line 193, in execute_callable
    return self.python_callable(*self.op_args, **self.op_kwargs)
  File "/opt/airflow/dags/forex_data_pipeline.py", line 25, in download_rates
    with open("/opt/files/rates.json", "w") as outfil:
FileNotFoundError: [Errno 2] No such file or directory: '/opt/files/rates.json'

During handling of the above exception, another exception occurred:

Traceback (most recent call last):
  File "/home/airflow/.local/lib/python3.7/site-packages/airflow/models/taskinstance.py", line 2315, in email_alert
    send_email(task.email, subject, html_content)
  File "/home/airflow/.local/lib/python3.7/site-packages/airflow/utils/email.py", line 72, in send_email
    **kwargs,
  File "/home/airflow/.local/lib/python3.7/site-packages/airflow/utils/email.py", line 120, in send_email_smtp
    send_mime_email(e_from=mail_from, e_to=recipients, mime_msg=msg, conn_id=conn_id, dryrun=dryrun)
  File "/home/airflow/.local/lib/python3.7/site-packages/airflow/utils/email.py", line 231, in send_mime_email
    smtp_conn = _get_smtp_connection(smtp_host, smtp_port, smtp_timeout, smtp_ssl)
  File "/home/airflow/.local/lib/python3.7/site-packages/airflow/utils/email.py", line 265, in _get_smtp_connection
    else smtplib.SMTP(host=host, port=port, timeout=timeout)
  File "/usr/local/lib/python3.7/smtplib.py", line 251, in __init__
    (code, msg) = self.connect(host, port)
  File "/usr/local/lib/python3.7/smtplib.py", line 336, in connect
    self.sock = self._get_socket(host, port, self.timeout)
  File "/usr/local/lib/python3.7/smtplib.py", line 307, in _get_socket
    self.source_address)
  File "/usr/local/lib/python3.7/socket.py", line 728, in create_connection
    raise err
  File "/usr/local/lib/python3.7/socket.py", line 716, in create_connection
    sock.connect(sa)
OSError: [Errno 99] Cannot assign requested address

During handling of the above exception, another exception occurred:

Traceback (most recent call last):
  File "/home/airflow/.local/lib/python3.7/site-packages/airflow/models/taskinstance.py", line 1912, in handle_failure
    self.email_alert(error, task)
  File "/home/airflow/.local/lib/python3.7/site-packages/airflow/models/taskinstance.py", line 2317, in email_alert
    send_email(task.email, subject, html_content_err)
  File "/home/airflow/.local/lib/python3.7/site-packages/airflow/utils/email.py", line 72, in send_email
    **kwargs,
  File "/home/airflow/.local/lib/python3.7/site-packages/airflow/utils/email.py", line 120, in send_email_smtp
    send_mime_email(e_from=mail_from, e_to=recipients, mime_msg=msg, conn_id=conn_id, dryrun=dryrun)
  File "/home/airflow/.local/lib/python3.7/site-packages/airflow/utils/email.py", line 231, in send_mime_email
    smtp_conn = _get_smtp_connection(smtp_host, smtp_port, smtp_timeout, smtp_ssl)
  File "/home/airflow/.local/lib/python3.7/site-packages/airflow/utils/email.py", line 265, in _get_smtp_connection
    else smtplib.SMTP(host=host, port=port, timeout=timeout)
  File "/usr/local/lib/python3.7/smtplib.py", line 251, in __init__
    (code, msg) = self.connect(host, port)
  File "/usr/local/lib/python3.7/smtplib.py", line 336, in connect
    self.sock = self._get_socket(host, port, self.timeout)
  File "/usr/local/lib/python3.7/smtplib.py", line 307, in _get_socket
    self.source_address)
  File "/usr/local/lib/python3.7/socket.py", line 728, in create_connection
    raise err
  File "/usr/local/lib/python3.7/socket.py", line 716, in create_connection
    sock.connect(sa)
OSError: [Errno 99] Cannot assign requested address
[2022-11-08T22:33:38.183+0000] {standard_task_runner.py:107} ERROR - Failed to execute job 22 for task downloading_rates ([Errno 2] No such file or directory: '/opt/files/rates.json'; 4884)
[2022-11-08T22:33:38.234+0000] {local_task_job.py:164} INFO - Task exited with return code 1
[2022-11-08T22:33:38.257+0000] {local_task_job.py:273} INFO - 0 downstream tasks scheduled from follow-on schedule check
