[2022-11-08T22:29:58.588+0000] {taskinstance.py:1165} INFO - Dependencies all met for <TaskInstance: forex_data_pipeline.downloading_rates manual__2022-11-08T22:19:47.299012+00:00 [queued]>
[2022-11-08T22:29:58.604+0000] {taskinstance.py:1165} INFO - Dependencies all met for <TaskInstance: forex_data_pipeline.downloading_rates manual__2022-11-08T22:19:47.299012+00:00 [queued]>
[2022-11-08T22:29:58.605+0000] {taskinstance.py:1362} INFO - 
--------------------------------------------------------------------------------
[2022-11-08T22:29:58.606+0000] {taskinstance.py:1363} INFO - Starting attempt 5 of 7
[2022-11-08T22:29:58.606+0000] {taskinstance.py:1364} INFO - 
--------------------------------------------------------------------------------
[2022-11-08T22:29:58.621+0000] {taskinstance.py:1383} INFO - Executing <Task(PythonOperator): downloading_rates> on 2022-11-08 22:19:47.299012+00:00
[2022-11-08T22:29:58.626+0000] {standard_task_runner.py:54} INFO - Started process 4702 to run task
[2022-11-08T22:29:58.629+0000] {standard_task_runner.py:82} INFO - Running: ['***', 'tasks', 'run', 'forex_data_pipeline', 'downloading_rates', 'manual__2022-11-08T22:19:47.299012+00:00', '--job-id', '17', '--raw', '--subdir', 'DAGS_FOLDER/forex_data_pipeline.py', '--cfg-path', '/tmp/tmptxplhnqf']
[2022-11-08T22:29:58.630+0000] {standard_task_runner.py:83} INFO - Job 17: Subtask downloading_rates
[2022-11-08T22:29:58.631+0000] {dagbag.py:525} INFO - Filling up the DagBag from /opt/***/dags/forex_data_pipeline.py
[2022-11-08T22:29:58.735+0000] {task_command.py:384} INFO - Running <TaskInstance: forex_data_pipeline.downloading_rates manual__2022-11-08T22:19:47.299012+00:00 [running]> on host f6a61415b844
[2022-11-08T22:29:58.793+0000] {taskinstance.py:1592} INFO - Exporting the following env vars:
AIRFLOW_CTX_DAG_EMAIL=juanfelipehdezm@gmail.com
AIRFLOW_CTX_DAG_OWNER=felipehdez
AIRFLOW_CTX_DAG_ID=forex_data_pipeline
AIRFLOW_CTX_TASK_ID=downloading_rates
AIRFLOW_CTX_EXECUTION_DATE=2022-11-08T22:19:47.299012+00:00
AIRFLOW_CTX_TRY_NUMBER=5
AIRFLOW_CTX_DAG_RUN_ID=manual__2022-11-08T22:19:47.299012+00:00
[2022-11-08T22:29:59.381+0000] {taskinstance.py:1851} ERROR - Task failed with exception
Traceback (most recent call last):
  File "/home/airflow/.local/lib/python3.7/site-packages/airflow/operators/python.py", line 175, in execute
    return_value = self.execute_callable()
  File "/home/airflow/.local/lib/python3.7/site-packages/airflow/operators/python.py", line 193, in execute_callable
    return self.python_callable(*self.op_args, **self.op_kwargs)
  File "/opt/airflow/dags/forex_data_pipeline.py", line 25, in download_rates
    with open("/temp/rates.json", "w") as outfil:
FileNotFoundError: [Errno 2] No such file or directory: '/temp/rates.json'
[2022-11-08T22:29:59.396+0000] {taskinstance.py:1406} INFO - Marking task as UP_FOR_RETRY. dag_id=forex_data_pipeline, task_id=downloading_rates, execution_date=20221108T221947, start_date=20221108T222958, end_date=20221108T222959
[2022-11-08T22:29:59.412+0000] {warnings.py:110} WARNING - /home/***/.local/lib/python3.7/site-packages/***/utils/email.py:120: RemovedInAirflow3Warning: Fetching SMTP credentials from configuration variables will be deprecated in a future release. Please set credentials using a connection instead.
  send_mime_email(e_from=mail_from, e_to=recipients, mime_msg=msg, conn_id=conn_id, dryrun=dryrun)

[2022-11-08T22:29:59.413+0000] {configuration.py:569} WARNING - section/key [smtp/smtp_user] not found in config
[2022-11-08T22:29:59.414+0000] {email.py:229} INFO - Email alerting: attempt 1
[2022-11-08T22:29:59.420+0000] {configuration.py:569} WARNING - section/key [smtp/smtp_user] not found in config
[2022-11-08T22:29:59.421+0000] {email.py:229} INFO - Email alerting: attempt 1
[2022-11-08T22:29:59.421+0000] {taskinstance.py:1914} ERROR - Failed to send email to: juanfelipehdezm@gmail.com
Traceback (most recent call last):
  File "/home/airflow/.local/lib/python3.7/site-packages/airflow/models/taskinstance.py", line 1457, in _run_raw_task
    self._execute_task_with_callbacks(context, test_mode)
  File "/home/airflow/.local/lib/python3.7/site-packages/airflow/models/taskinstance.py", line 1603, in _execute_task_with_callbacks
    result = self._execute_task(context, task_orig)
  File "/home/airflow/.local/lib/python3.7/site-packages/airflow/models/taskinstance.py", line 1664, in _execute_task
    result = execute_callable(context=context)
  File "/home/airflow/.local/lib/python3.7/site-packages/airflow/operators/python.py", line 175, in execute
    return_value = self.execute_callable()
  File "/home/airflow/.local/lib/python3.7/site-packages/airflow/operators/python.py", line 193, in execute_callable
    return self.python_callable(*self.op_args, **self.op_kwargs)
  File "/opt/airflow/dags/forex_data_pipeline.py", line 25, in download_rates
    with open("/temp/rates.json", "w") as outfil:
FileNotFoundError: [Errno 2] No such file or directory: '/temp/rates.json'

During handling of the above exception, another exception occurred:

Traceback (most recent call last):
  File "/home/airflow/.local/lib/python3.7/site-packages/airflow/models/taskinstance.py", line 2315, in email_alert
    send_email(task.email, subject, html_content)
  File "/home/airflow/.local/lib/python3.7/site-packages/airflow/utils/email.py", line 72, in send_email
    **kwargs,
  File "/home/airflow/.local/lib/python3.7/site-packages/airflow/utils/email.py", line 120, in send_email_smtp
    send_mime_email(e_from=mail_from, e_to=recipients, mime_msg=msg, conn_id=conn_id, dryrun=dryrun)
  File "/home/airflow/.local/lib/python3.7/site-packages/airflow/utils/email.py", line 231, in send_mime_email
    smtp_conn = _get_smtp_connection(smtp_host, smtp_port, smtp_timeout, smtp_ssl)
  File "/home/airflow/.local/lib/python3.7/site-packages/airflow/utils/email.py", line 265, in _get_smtp_connection
    else smtplib.SMTP(host=host, port=port, timeout=timeout)
  File "/usr/local/lib/python3.7/smtplib.py", line 251, in __init__
    (code, msg) = self.connect(host, port)
  File "/usr/local/lib/python3.7/smtplib.py", line 336, in connect
    self.sock = self._get_socket(host, port, self.timeout)
  File "/usr/local/lib/python3.7/smtplib.py", line 307, in _get_socket
    self.source_address)
  File "/usr/local/lib/python3.7/socket.py", line 728, in create_connection
    raise err
  File "/usr/local/lib/python3.7/socket.py", line 716, in create_connection
    sock.connect(sa)
OSError: [Errno 99] Cannot assign requested address

During handling of the above exception, another exception occurred:

Traceback (most recent call last):
  File "/home/airflow/.local/lib/python3.7/site-packages/airflow/models/taskinstance.py", line 1912, in handle_failure
    self.email_alert(error, task)
  File "/home/airflow/.local/lib/python3.7/site-packages/airflow/models/taskinstance.py", line 2317, in email_alert
    send_email(task.email, subject, html_content_err)
  File "/home/airflow/.local/lib/python3.7/site-packages/airflow/utils/email.py", line 72, in send_email
    **kwargs,
  File "/home/airflow/.local/lib/python3.7/site-packages/airflow/utils/email.py", line 120, in send_email_smtp
    send_mime_email(e_from=mail_from, e_to=recipients, mime_msg=msg, conn_id=conn_id, dryrun=dryrun)
  File "/home/airflow/.local/lib/python3.7/site-packages/airflow/utils/email.py", line 231, in send_mime_email
    smtp_conn = _get_smtp_connection(smtp_host, smtp_port, smtp_timeout, smtp_ssl)
  File "/home/airflow/.local/lib/python3.7/site-packages/airflow/utils/email.py", line 265, in _get_smtp_connection
    else smtplib.SMTP(host=host, port=port, timeout=timeout)
  File "/usr/local/lib/python3.7/smtplib.py", line 251, in __init__
    (code, msg) = self.connect(host, port)
  File "/usr/local/lib/python3.7/smtplib.py", line 336, in connect
    self.sock = self._get_socket(host, port, self.timeout)
  File "/usr/local/lib/python3.7/smtplib.py", line 307, in _get_socket
    self.source_address)
  File "/usr/local/lib/python3.7/socket.py", line 728, in create_connection
    raise err
  File "/usr/local/lib/python3.7/socket.py", line 716, in create_connection
    sock.connect(sa)
OSError: [Errno 99] Cannot assign requested address
[2022-11-08T22:29:59.437+0000] {standard_task_runner.py:107} ERROR - Failed to execute job 17 for task downloading_rates ([Errno 2] No such file or directory: '/temp/rates.json'; 4702)
[2022-11-08T22:29:59.484+0000] {local_task_job.py:164} INFO - Task exited with return code 1
[2022-11-08T22:29:59.517+0000] {local_task_job.py:273} INFO - 0 downstream tasks scheduled from follow-on schedule check
